<mujoco model="mug">
  <visual>
    <headlight ambient="0 0 0" diffuse="0 0 0" specular="1 1 1"/>
    <quality shadowsize="8192"/>
  </visual>

  <asset>
    <material name="whiteMug" rgba="1 1 1 1"/>
    <material name="grayMug" rgba="0.753 0.753 0.753 1"/>
    <mesh file="mug.obj" scale=".01 .01 .01"/>
    <material name="floor" reflectance=".1"/>
  </asset>

  <default>
    <default class="collision">
      <geom type="box" group="3"/>
      <default class="cup">
        <geom size="0.0026 0.00704 0.033"/>
      </default>
      <default class="handle">
        <geom size="0.0025 0.00328 0.0055"/>
      </default>
    </default>
  </default>

  <worldbody>
    <body name="mug" pos="0 0.05 0.2">
      <joint axis="1 0 0" name="rotate_x" pos="0 0 0.05" type="hinge" range="0 180" damping="0.25"/>
      <geom type="mesh" mesh="mug" material="grayMug" euler="90 0 0" group="1" contype="0" conaffinity="0"/>
      <geom class="cup" pos="0.0418 0 0.038" euler="0 0 0"/>
      <geom class="cup" pos="0.0398 0.0129 0.038" euler="0 0 18"/>
      <geom class="cup" pos="0.0339 0.0246 0.038" euler="0 0 36"/>
      <geom class="cup" pos="0.0246 0.0339 0.038" euler="0 0 54"/>
      <geom class="cup" pos="0.0129 0.0398 0.038" euler="0 0 72"/>
      <geom class="cup" pos="0 0.0418 0.038" euler="0 0 90"/>
      <geom class="cup" pos="-0.0129 0.0398 0.038" euler="0 0 108"/>
      <geom class="cup" pos="-0.0246 0.0339 0.038" euler="0 0 126"/>
      <geom class="cup" pos="-0.0339 0.0246 0.038" euler="0 0 144"/>
      <geom class="cup" pos="-0.0398 0.0129 0.038" euler="0 0 162"/>
      <geom class="cup" pos="-0.0418 0 0.038" euler="0 0 180"/>
      <geom class="cup" pos="-0.0398 -0.0129 0.038" euler="0 0 198"/>
      <geom class="cup" pos="-0.0339 -0.0246 0.038" euler="0 0 216"/>
      <geom class="cup" pos="-0.0246 -0.0339 0.038" euler="0 0 234"/>
      <geom class="cup" pos="-0.0129 -0.0398 0.038" euler="0 0 252"/>
      <geom class="cup" pos="0 -0.0418 0.038" euler="0 0 270"/>
      <geom class="cup" pos="0.0129 -0.0398 0.038" euler="0 0 288"/>
      <geom class="cup" pos="0.0246 -0.0339 0.038" euler="0 0 306"/>
      <geom class="cup" pos="0.0339 -0.0246 0.038" euler="0 0 324"/>
      <geom class="cup" pos="0.0398 -0.0129 0.038" euler="0 0 342"/>
      <geom class="cup" type="cylinder" size="0.045 0.0026" pos="0 0 0.0026"/>
      <body name="handle" pos="0.056 0 0.0395" euler="90 0 0">
        <geom class="handle" pos="0.0193 0 0" euler="0 0 0"/>
        <geom class="handle" pos="0.0184 0.00568 0" euler="0 0 17.1"/>
        <geom class="handle" pos="0.0159 0.0108 0" euler="0 0 34.3"/>
        <geom class="handle" pos="0.012 0.0151 0" euler="0 0 51.4"/>
        <geom class="handle" pos="0.00703 0.0179 0" euler="0 0 68.6"/>
        <geom class="handle" pos="0.00144 0.0192 0" euler="0 0 85.7"/>
        <geom class="handle" pos="0.00144 -0.0192 0" euler="0 0 274"/>
        <geom class="handle" pos="0.00703 -0.0179 0" euler="0 0 291"/>
        <geom class="handle" pos="0.012 -0.0151 0" euler="0 0 309"/>
        <geom class="handle" pos="0.0159 -0.0108 0" euler="0 0 326"/>
        <geom class="handle" pos="0.0184 -0.00568 0" euler="0 0 343"/>
        <geom class="collision" size="0.007 0.0025 0.0055" pos="-0.007 -0.0195 0"/>
        <geom class="collision" size="0.007 0.0025 0.0055" pos="-0.007 0.0195 0"/>
      </body>
    </body>

    <body name="mugStatic" pos="0 -0.01 0">
      <geom type="mesh" mesh="mug" material="whiteMug" euler="90 0 0" group="1" contype="0" conaffinity="0"/>
      <geom class="cup" pos="0.0418 0 0.038" euler="0 0 0"/>
      <geom class="cup" pos="0.0398 0.0129 0.038" euler="0 0 18"/>
      <geom class="cup" pos="0.0339 0.0246 0.038" euler="0 0 36"/>
      <geom class="cup" pos="0.0246 0.0339 0.038" euler="0 0 54"/>
      <geom class="cup" pos="0.0129 0.0398 0.038" euler="0 0 72"/>
      <geom class="cup" pos="0 0.0418 0.038" euler="0 0 90"/>
      <geom class="cup" pos="-0.0129 0.0398 0.038" euler="0 0 108"/>
      <geom class="cup" pos="-0.0246 0.0339 0.038" euler="0 0 126"/>
      <geom class="cup" pos="-0.0339 0.0246 0.038" euler="0 0 144"/>
      <geom class="cup" pos="-0.0398 0.0129 0.038" euler="0 0 162"/>
      <geom class="cup" pos="-0.0418 0 0.038" euler="0 0 180"/>
      <geom class="cup" pos="-0.0398 -0.0129 0.038" euler="0 0 198"/>
      <geom class="cup" pos="-0.0339 -0.0246 0.038" euler="0 0 216"/>
      <geom class="cup" pos="-0.0246 -0.0339 0.038" euler="0 0 234"/>
      <geom class="cup" pos="-0.0129 -0.0398 0.038" euler="0 0 252"/>
      <geom class="cup" pos="0 -0.0418 0.038" euler="0 0 270"/>
      <geom class="cup" pos="0.0129 -0.0398 0.038" euler="0 0 288"/>
      <geom class="cup" pos="0.0246 -0.0339 0.038" euler="0 0 306"/>
      <geom class="cup" pos="0.0339 -0.0246 0.038" euler="0 0 324"/>
      <geom class="cup" pos="0.0398 -0.0129 0.038" euler="0 0 342"/>
      <geom class="cup" type="cylinder" size="0.045 0.0026" pos="0 0 0.0026"/>
      <body name="handleStatic" pos="0.056 0 0.0395" euler="90 0 0">
        <geom class="handle" pos="0.0193 0 0" euler="0 0 0"/>
        <geom class="handle" pos="0.0184 0.00568 0" euler="0 0 17.1"/>
        <geom class="handle" pos="0.0159 0.0108 0" euler="0 0 34.3"/>
        <geom class="handle" pos="0.012 0.0151 0" euler="0 0 51.4"/>
        <geom class="handle" pos="0.00703 0.0179 0" euler="0 0 68.6"/>
        <geom class="handle" pos="0.00144 0.0192 0" euler="0 0 85.7"/>
        <geom class="handle" pos="0.00144 -0.0192 0" euler="0 0 274"/>
        <geom class="handle" pos="0.00703 -0.0179 0" euler="0 0 291"/>
        <geom class="handle" pos="0.012 -0.0151 0" euler="0 0 309"/>
        <geom class="handle" pos="0.0159 -0.0108 0" euler="0 0 326"/>
        <geom class="handle" pos="0.0184 -0.00568 0" euler="0 0 343"/>
        <geom class="collision" size="0.007 0.0025 0.0055" pos="-0.007 -0.0195 0"/>
        <geom class="collision" size="0.007 0.0025 0.0055" pos="-0.007 0.0195 0"/>
      </body>
    </body>

    <body name="particle_0" pos="0.008660254037844387 0.054999999999999999 0.25">
      <freejoint />
      <geom name="particle_0" type="sphere" size="0.0070" rgba="1 0 0 1" solref=".005 1" mass="0.005" contype="1" conaffinity="1" friction="1 1 1" />
    </body>
    <body name="particle_1" pos="-0.006291558324094168 0.0469314019725 0.25">
      <freejoint />
      <geom name="particle_1" type="sphere" size="0.0070" rgba="1 .5 0 1" solref=".005 1" mass="0.005" contype="1" conaffinity="1" friction="1 1 1" />
    </body>
    <body name="particle_2" pos="0.006000000000000002 0.0396076951546 0.25">
      <freejoint />
      <geom name="particle_2" type="sphere" size="0.0070" rgba="1 .5 .5  1" solref=".005 1" mass="0.005" contype="1" conaffinity="1" friction="1 1 1" />
    </body>
    <body name="particle_3" pos="0.022299533810498175 0.0284655905158 0.25">
      <freejoint />
      <geom name="particle_3" type="sphere" size="0.0070" rgba="0 0 1 1" solref=".005 1" mass="0.005" contype="1" conaffinity="1" friction="1 1 1" />
    </body>
    <body name="particle_4" pos="-0.003364647586332771 0.062557035741757887 0.25">
      <freejoint />
      <geom name="particle_4" type="sphere" size="0.0070" rgba="0 1 .5 1" solref=".005 1" mass="0.005" contype="1" conaffinity="1" friction="1 1 1" />
    </body>
    <body name="particle_5" pos="-0.0018834247910913906 0.023065770643 0.25">
      <freejoint />
      <geom name="particle_5" type="sphere" size="0.0070" rgba=".5 1 .5 1" solref=".005 1" mass="0.005" contype="1" conaffinity="1" friction="1 1 1" />
    </body>
    <body name="particle_6" pos="0.022384014458986124 0.065098208393710167 0.25">
      <freejoint />
      <geom name="particle_6" type="sphere" size="0.0070" rgba=".0 0 1 1" solref=".005 1" mass="0.005" contype="1" conaffinity="1" friction="1 1 1" />
    </body>
    <body name="particle_7" pos="-0.019965887751182323 0.0349546244212 0.25">
      <freejoint />
      <geom name="particle_7" type="sphere" size="0.0070" rgba=".5 0 1 1" solref=".005 1" mass="0.005" contype="1" conaffinity="1" friction="1 1 1" />
    </body>
    <body name="particle_8" pos="-0.03098111563759197 0.0489181156022 0.25">
      <freejoint />
      <geom name="particle_8" type="sphere" size="0.0070" rgba=".5 .5 1 1" solref=".005 1" mass="0.005" contype="1" conaffinity="1" friction="1 1 1" />
    </body>
    <body name="particle_9" pos="0.020843469184467764 0.0474407437885 0.25">
      <freejoint />
      <geom name="particle_9" type="sphere" size="0.0070" rgba=".5 .5 .5 1" solref=".005 1" mass="0.005" contype="1" conaffinity="1" friction="1 1 1" />
    </body>
  </worldbody>

  <actuator>
      <motor name="rotate_x_motor" joint="rotate_x" ctrllimited="true" ctrlrange="-1.0 1.0" />
  </actuator>
</mujoco>
